Workbook
Name CV_22: '2023-2025'!$E$45
Name CV_23: '2023-2025'!$D$45
Name CV_24: '2023-2025'!$C$45
Name PASIV_22: '2023-2025'!$I$15
Name PASIV_23: '2023-2025'!$H$15
Name PASIV_24: '2023-2025'!$G$15
Name PATRI_23: '2023-2025'!$H$29
Name PATRI_24: '2023-2025'!$G$29
Name PATRIM_22: '2023-2025'!$I$29
Name UTI_22: '2023-2025'!$E$67
Name UTI_23: '2023-2025'!$D$67
Name UTI_24: '2023-2025'!$C$67
Name VENTAS_22: '2023-2025'!$E$44
Name VENTAS_23: '2023-2025'!$D$44
Name VENTAS_24: '2023-2025'!$C$44

Sheet 2023
B3: Activo | D3: Pasivo | H3: VENTAS | I3: =+C42 -> 0 | K3: CUADRE | L3: =+C35-E32 -> 0
B4: Efectivo y equivalentes de efectivo | D4: Sobregiros bancarios | H4: UTILIDAD | I4: =+E27 -> 0
B5: Inversiones financieras | D5: Trib. y aport. sist. pens. y salud por pagar | H5: USS | I5: =+I4/3.8 -> 0
B6: Ctas. por cobrar comerciales - ter. | D6: Remuneraciones y particip. por pagar
B7: Ctas. por cobrar comerciales - relac. | D7: Ctas. por pagar comerciales - terceros | H7: Activo
B8: Cuentas por cobrar al personal, acc(socios) y directores | D8: Ctas. por pagar comerciales - relac. | H8: Pasivo
B9: Ctas. por cobrar diversas - terceros | D9: Ctas por pagar accionist(soc, partic) y direct | H9: Patrimonio
B10: Ctas. por cobrar diversas - relacionados | D10: Ctas. por pagar diversas - terceros
B11: Serv. y otros contratados por anticipado | D11: Ctas. por pagar diversas - relacionadas | H11: Liquidez corriente | I11: =SUM(C4:C12) -> 0 | J11: =SUM(E4:E11) -> 0 | K11: =SUM(C4:C11)/SUM(E4:E11) -> #DIV/0!
B12: Estimacio de ctas. de cobranza dudosa | D12: Obligaciones financieras | H12: Prueba Acida | I12: =SUM(C4:C12) -> 0 | J12: =SUM(E4:E14) -> 0 | K12: =SUM(C4:C11)/SUM(E4:E14) -> #DIV/0!
B13: Mercaderías | D13: Provisiones | H13: Endeudamiento | I13: =SUM(E4:E14) -> 0 | J13: =SUM(E18:E28) -> 0 | K13: =I13/J13 -> #DIV/0!
B14: Productos terminados | D14: Pago diferido | H14: Margen | K14: =+I4/I3 -> #DIV/0!
B15: Subproductos, deshechos y desperdicios | D15: TOTAL PASIVO | E15: =SUM(E4:E14) -> 0
B16: Productos en proceso | H16: Rentabilidad | I16: =+I4 -> 0 | J16: 0 | K16: =+I16/J16 -> #DIV/0!
B17: Materias primas | H17: Gestion | I17: 0 | J17: 0 | K17: =+I17/J17 -> #DIV/0!
B18: Materias aux, suministros y repuestos | D18: Capital
B19: Envases y embalajes | D19: Acciones de inversión
B20: Inventarios por recibir | D20: Capital adicional positivo
B21: Desvalorización de inventarios | D21: Capital adicional negativos
B22: Activos no ctes. mantenidos por la vta | D22: Resultados no realizados
B23: Otros activos corrientes | D23: Excedentes de evaluacion
B24: Inversiones mobiliarias | D24: Reservas
B25: Propiedades de inversión (1) | D25: Resultados acumulados positivos
B26: Activos por derecho de uso (2) | D26: Resultados acumulados negativos
B27: Propiedades, planta y equipo | D27: Utilidad del ejercicio
B28: Depreciación de 1,2 y PPE acumulados | D28: Pérdida del ejercicio
B29: Intangibles | D29: TOTAL PATRIMONIO | E29: =SUM(E18:E28) -> 0
B30: Activos biologicos
B31: Deprec act biologico y amortiz acumulada
B32: Desvalorizacióo de activo inmovilizado | D32: TOTAL PASIVO Y PATRIMONIO | E32: =+E29+E15 -> 0
B33: Activo diferido
B34: Otros activos no corrientes
B35: TOTAL ACTIVO | C35: =SUM(C4:C34) -> 0
B41: ESTADO DE RESULTADO
B42: Ventas netas o ing por servicios
B43: Desc , rebajas y bonif concedidas | C43: 0
B44: Ventas netas | C44: =+SUM(C42:C43) -> 0
B45: Costo de ventas
B46: Resultado bruto Utilidad | C46: =+IF(SUM(C44:C45)<0,0,SUM(C44:C45)) -> 0
B47: Resultado bruto Pérdida | C47: =+IF(SUM(C44:C45)<0,SUM(C44:C45),0) -> 0
...

Sheet 2024
B3: Activo | D3: Pasivo | H3: VENTAS | I3: =+C42 -> 0 | K3: CUADRE | L3: =+C35-E32 -> 0
B4: Efectivo y equivalentes de efectivo | D4: Sobregiros bancarios | H4: UTILIDAD | I4: =+E27 -> 0
B5: Inversiones financieras | D5: Trib. y aport. sist. pens. y salud por pagar | H5: USS | I5: =+I4/3.8 -> 0
B6: Ctas. por cobrar comerciales - ter. | D6: Remuneraciones y particip. por pagar
B7: Ctas. por cobrar comerciales - relac. | D7: Ctas. por pagar comerciales - terceros | H7: Activo
B8: Cuentas por cobrar al personal, acc(socios) y directores | D8: Ctas. por pagar comerciales - relac. | H8: Pasivo
B9: Ctas. por cobrar diversas - terceros | D9: Ctas por pagar accionist(soc, partic) y direct | H9: Patrimonio
B10: Ctas. por cobrar diversas - relacionados | D10: Ctas. por pagar diversas - terceros
B11: Serv. y otros contratados por anticipado | D11: Ctas. por pagar diversas - relacionadas | H11: Liquidez corriente | I11: =SUM(C4:C12) -> 0 | J11: =SUM(E4:E11) -> 0 | K11: =SUM(C4:C11)/SUM(E4:E11) -> #DIV/0!
B12: Estimacio de ctas. de cobranza dudosa | D12: Obligaciones financieras | H12: Prueba Acida | I12: =SUM(C4:C12) -> 0 | J12: =SUM(E4:E14) -> 0 | K12: =SUM(C4:C11)/SUM(E4:E14) -> #DIV/0!
B13: Mercaderías | D13: Provisiones | H13: Endeudamiento | I13: =SUM(E4:E14) -> 0 | J13: =SUM(E18:E28) -> 0 | K13: =I13/J13 -> #DIV/0!
B14: Productos terminados | D14: Pago diferido | H14: Margen | K14: =+I4/I3 -> #DIV/0!
B15: Subproductos, deshechos y desperdicios | D15: TOTAL PASIVO | E15: =SUM(E4:E14) -> 0 | H15: Rentabilidad | I15: 0 | J15: 0 | K15: =+I15/J15 -> #DIV/0!
B16: Productos en proceso | H16: Gestion | I16: 0 | J16: 0 | K16: =+I16/J16 -> #DIV/0!
B17: Materias primas
B18: Materias aux, suministros y repuestos | D18: Capital
B19: Envases y embalajes | D19: Acciones de inversión
B20: Inventarios por recibir | D20: Capital adicional positivo
B21: Desvalorización de inventarios | D21: Capital adicional negativos
B22: Activos no ctes. mantenidos por la vta | D22: Resultados no realizados
B23: Otros activos corrientes | D23: Excedentes de evaluacion
B24: Inversiones mobiliarias | D24: Reservas
B25: Propiedades de inversión (1) | D25: Resultados acumulados positivos
B26: Activos por derecho de uso (2) | D26: Resultados acumulados negativos
B27: Propiedades, planta y equipo | D27: Utilidad del ejercicio
B28: Depreciación de 1,2 y PPE acumulados | D28: Pérdida del ejercicio
B29: Intangibles | D29: TOTAL PATRIMONIO | E29: =SUM(E18:E28) -> 0
B30: Activos biologicos
B31: Deprec act biologico y amortiz acumulada
B32: Desvalorizacióo de activo inmovilizado | D32: TOTAL PASIVO Y PATRIMONIO | E32: =+E29+E15 -> 0
B33: Activo diferido
B34: Otros activos no corrientes
B35: TOTAL ACTIVO | C35: =SUM(C4:C34) -> 0
B41: ESTADO DE RESULTADO
B42: Ventas netas o ing por servicios
B43: Desc , rebajas y bonif concedidas | C43: 0
B44: Ventas netas | C44: =+SUM(C42:C43) -> 0
B45: Costo de ventas
B46: Resultado bruto Utilidad | C46: =+IF(SUM(C44:C45)<0,0,SUM(C44:C45)) -> 0
B47: Resultado bruto Pérdida | C47: =+IF(SUM(C44:C45)<0,SUM(C44:C45),0) -> 0
...

Sheet 2025
B3: Activo | D3: Pasivo | H3: VENTAS | I3: =C42 -> 0 | K3: CUADRE | L3: =+C35-E32 -> 0
B4: Efectivo y equivalentes de efectivo | D4: Sobregiros bancarios | H4: UTILIDAD | I4: =+E27 -> 0
B5: Inversiones financieras | D5: Trib. y aport. sist. pens. y salud por pagar | H5: USS | I5: =+I4/3.8 -> 0
B6: Ctas. por cobrar comerciales - ter. | D6: Remuneraciones y particip. por pagar
B7: Ctas. por cobrar comerciales - relac. | D7: Ctas. por pagar comerciales - terceros | H7: Activo
B8: Cuentas por cobrar al personal, acc(socios) y directores | D8: Ctas. por pagar comerciales - relac. | H8: Pasivo
B9: Ctas. por cobrar diversas - terceros | D9: Ctas por pagar accionist(soc, partic) y direct | H9: Patrimonio
B10: Ctas. por cobrar diversas - relacionados | D10: Ctas. por pagar diversas - terceros
B11: Serv. y otros contratados por anticipado | D11: Ctas. por pagar diversas - relacionadas | H11: Liquidez corriente | I11: =SUM(C4:C12) -> 0 | J11: =SUM(E4:E11) -> 0 | K11: =SUM(C4:C11)/SUM(E4:E11) -> #DIV/0!
B12: Estimacio de ctas. de cobranza dudosa | D12: Obligaciones financieras | H12: Prueba Acida | I12: =SUM(C4:C12) -> 0 | J12: =SUM(E4:E14) -> 0 | K12: =SUM(C4:C11)/SUM(E4:E14) -> #DIV/0!
B13: Mercaderías | D13: Provisiones | H13: Endeudamiento | I13: =SUM(E4:E14) -> 0 | J13: =SUM(E18:E28) -> 0 | K13: =I13/J13 -> #DIV/0!
B14: Productos terminados | D14: Pago diferido | H14: Margen | K14: =+I4/I3 -> #DIV/0!
B15: Subproductos, deshechos y desperdicios | D15: TOTAL PASIVO | E15: =SUM(E4:E14) -> 0 | H15: Rentabilidad | I15: =+I4 -> 0 | J15: =+I3 -> 0 | K15: =+I15/J15 -> #DIV/0!
B16: Productos en proceso | H16: Gestion | I16: 0 | J16: 0 | K16: =+-C42/C45 -> #DIV/0!
B17: Materias primas
B18: Materias aux, suministros y repuestos | D18: Capital
B19: Envases y embalajes | D19: Acciones de inversión
B20: Inventarios por recibir | D20: Capital adicional positivo
B21: Desvalorización de inventarios | D21: Capital adicional negativos
B22: Activos no ctes. mantenidos por la vta | D22: Resultados no realizados
B23: Otros activos corrientes | D23: Excedentes de evaluacion
B24: Inversiones mobiliarias | D24: Reservas
B25: Propiedades de inversión (1) | D25: Resultados acumulados positivos
B26: Activos por derecho de uso (2) | D26: Resultados acumulados negativos
B27: Propiedades, planta y equipo | D27: Utilidad del ejercicio
B28: Depreciación de 1,2 y PPE acumulados | D28: Pérdida del ejercicio
B29: Intangibles | D29: TOTAL PATRIMONIO | E29: =SUM(E18:E28) -> 0
B30: Activos biologicos
B31: Deprec act biologico y amortiz acumulada
B32: Desvalorizacióo de activo inmovilizado | D32: TOTAL PASIVO Y PATRIMONIO | E32: =+E29+E15 -> 0
B33: Activo diferido
B34: Otros activos no corrientes
B35: TOTAL ACTIVO | C35: =SUM(C4:C34) -> 0
B41: ESTADO DE RESULTADO
B42: Ventas netas o ing por servicios
B43: Desc , rebajas y bonif concedidas
B44: Ventas netas | C44: =+C42 -> 0
B45: Costo de ventas
B46: Resultado bruto Utilidad | C46: =+C44+C45 -> 0
B47: Resultado bruto Pérdida | C47: 0
...

Sheet 2023-2025
B1: FECHA DE INICIO DE ACTIVIDAD
B3: Activo | C3: 2025 | D3: 2024 | E3: 2023 | F3: Pasivo | G3: 2025 | H3: 2024 | I3: 2023
B4: Efectivo y equivalentes de efectivo | C4: ='2025'!C4 -> 0 | D4: ='2024'!C4 -> 0 | E4: ='2023'!C4 -> 0 | F4: Sobregiros bancarios | G4: ='2025'!E4 -> 0 | H4: ='2024'!E4 -> 0 | I4: ='2023'!E4 -> 0
B5: Inversiones financieras | C5: ='2025'!C5 -> 0 | D5: ='2024'!C5 -> 0 | E5: ='2023'!C5 -> 0 | F5: Trib. y aport. sist. pens. y salud por pagar | G5: ='2025'!E5 -> 0 | H5: ='2024'!E5 -> 0 | I5: ='2023'!E5 -> 0
B6: Ctas. por cobrar comerciales - ter. | C6: ='2025'!C6 -> 0 | D6: ='2024'!C6 -> 0 | E6: ='2023'!C6 -> 0 | F6: Remuneraciones y particip. por pagar | G6: ='2025'!E6 -> 0 | H6: ='2024'!E6 -> 0 | I6: ='2023'!E6 -> 0
B7: Ctas. por cobrar comerciales - relac. | C7: ='2025'!C7 -> 0 | D7: ='2024'!C7 -> 0 | E7: ='2023'!C7 -> 0 | F7: Ctas. por pagar comerciales - terceros | G7: ='2025'!E7 -> 0 | H7: ='2024'!E7 -> 0 | I7: ='2023'!E7 -> 0
B8: Cuentas por cobrar al personal, acc(socios) y directores | C8: ='2025'!C8 -> 0 | D8: ='2024'!C8 -> 0 | E8: ='2023'!C8 -> 0 | F8: Ctas. por pagar comerciales - relac. | G8: ='2025'!E8 -> 0 | H8: ='2024'!E8 -> 0 | I8: ='2023'!E8 -> 0
B9: Ctas. por cobrar diversas - terceros | C9: ='2025'!C9 -> 0 | D9: ='2024'!C9 -> 0 | E9: ='2023'!C9 -> 0 | F9: Ctas por pagar accionist(soc, partic) y direct | G9: ='2025'!E9 -> 0 | H9: ='2024'!E9 -> 0 | I9: ='2023'!E9 -> 0
B10: Ctas. por cobrar diversas - relacionados | C10: ='2025'!C10 -> 0 | D10: ='2024'!C10 -> 0 | E10: ='2023'!C10 -> 0 | F10: Ctas. por pagar diversas - terceros | G10: ='2025'!E10 -> 0 | H10: ='2024'!E10 -> 0 | I10: ='2023'!E10 -> 0
B11: Serv. y otros contratados por anticipado | C11: ='2025'!C11 -> 0 | D11: ='2024'!C11 -> 0 | E11: ='2023'!C11 -> 0 | F11: Ctas. por pagar diversas - relacionadas | G11: ='2025'!E11 -> 0 | H11: ='2024'!E11 -> 0 | I11: ='2023'!E11 -> 0
B12: Estimacio de ctas. de cobranza dudosa | C12: ='2025'!C12 -> 0 | D12: ='2024'!C12 -> 0 | E12: ='2023'!C12 -> 0 | F12: Obligaciones financieras | G12: ='2025'!E12 -> 0 | H12: ='2024'!E12 -> 0 | I12: ='2023'!E12 -> 0
B13: Mercaderías | C13: ='2025'!C13 -> 0 | D13: ='2024'!C13 -> 0 | E13: ='2023'!C13 -> 0 | F13: Provisiones | G13: ='2025'!E13 -> 0 | H13: ='2024'!E13 -> 0 | I13: ='2023'!E13 -> 0
B14: Productos terminados | C14: ='2025'!C14 -> 0 | D14: ='2024'!C14 -> 0 | E14: ='2023'!C14 -> 0 | F14: Pago diferido | G14: ='2025'!E14 -> 0 | H14: ='2024'!E14 -> 0 | I14: ='2023'!E14 -> 0
B15: Subproductos, deshechos y desperdicios | C15: ='2025'!C15 -> 0 | D15: ='2024'!C15 -> 0 | E15: ='2023'!C15 -> 0 | F15: TOTAL PASIVO | G15: =SUM(G4:G14) -> 0 | H15: =SUM(H4:H14) -> 0 | I15: =SUM(I4:I14) -> 0
B16: Productos en proceso | C16: ='2025'!C16 -> 0 | D16: ='2024'!C16 -> 0 | E16: ='2023'!C16 -> 0
B17: Materias primas | C17: ='2025'!C17 -> 0 | D17: ='2024'!C17 -> 0 | E17: ='2023'!C17 -> 0
B18: Materias aux, suministros y repuestos | C18: ='2025'!C18 -> 0 | D18: ='2024'!C18 -> 0 | E18: ='2023'!C18 -> 0 | F18: Capital | G18: ='2025'!E18 -> 0 | H18: ='2024'!E18 -> 0 | I18: ='2023'!E18 -> 0
B19: Envases y embalajes | C19: ='2025'!C19 -> 0 | D19: ='2024'!C19 -> 0 | E19: ='2023'!C19 -> 0 | F19: Acciones de inversión | G19: ='2025'!E19 -> 0 | H19: ='2024'!E19 -> 0 | I19: ='2023'!E19 -> 0
B20: Inventarios por recibir | C20: ='2025'!C20 -> 0 | D20: ='2024'!C20 -> 0 | E20: ='2023'!C20 -> 0 | F20: Capital adicional positivo | G20: ='2025'!E20 -> 0 | H20: ='2024'!E20 -> 0 | I20: ='2023'!E20 -> 0
B21: Desvalorización de inventarios | C21: ='2025'!C21 -> 0 | D21: ='2024'!C21 -> 0 | E21: ='2023'!C21 -> 0 | F21: Capital adicional negativos | G21: ='2025'!E21 -> 0 | H21: ='2024'!E21 -> 0 | I21: ='2023'!E21 -> 0
B22: Activos no ctes. mantenidos por la vta | C22: ='2025'!C22 -> 0 | D22: ='2024'!C22 -> 0 | E22: ='2023'!C22 -> 0 | F22: Resultados no realizados | G22: ='2025'!E22 -> 0 | H22: ='2024'!E22 -> 0 | I22: ='2023'!E22 -> 0
B23: Otros activos corrientes | C23: ='2025'!C23 -> 0 | D23: ='2024'!C23 -> 0 | E23: ='2023'!C23 -> 0 | F23: Excedentes de evaluacion | G23: ='2025'!E23 -> 0 | H23: ='2024'!E23 -> 0 | I23: ='2023'!E23 -> 0
B24: Inversiones mobiliarias | C24: ='2025'!C24 -> 0 | D24: ='2024'!C24 -> 0 | E24: ='2023'!C24 -> 0 | F24: Reservas | G24: ='2025'!E24 -> 0 | H24: ='2024'!E24 -> 0 | I24: ='2023'!E24 -> 0
B25: Propiedades de inversión (1) | C25: ='2025'!C25 -> 0 | D25: ='2024'!C25 -> 0 | E25: ='2023'!C25 -> 0 | F25: Resultados acumulados positivos | G25: ='2025'!E25 -> 0 | H25: ='2024'!E25 -> 0 | I25: ='2023'!E25 -> 0
B26: Activos por derecho de uso (2) | C26: ='2025'!C26 -> 0 | D26: ='2024'!C26 -> 0 | E26: ='2023'!C26 -> 0 | F26: Resultados acumulados negativos | G26: ='2025'!E26 -> 0 | H26: ='2024'!E26 -> 0 | I26: ='2023'!E26 -> 0
B27: Propiedades, planta y equipo | C27: ='2025'!C27 -> 0 | D27: ='2024'!C27 -> 0 | E27: ='2023'!C27 -> 0 | F27: Utilidad del ejercicio | G27: ='2025'!E27 -> 0 | H27: ='2024'!E27 -> 0 | I27: ='2023'!E27 -> 0
B28: Depreciación de 1,2 y PPE acumulados | C28: ='2025'!C28 -> 0 | D28: ='2024'!C28 -> 0 | E28: ='2023'!C28 -> 0 | F28: Pérdida del ejercicio | G28: ='2025'!E28 -> 0 | H28: ='2024'!E28 -> 0 | I28: ='2023'!E28 -> 0
B29: Intangibles | C29: ='2025'!C29 -> 0 | D29: ='2024'!C29 -> 0 | E29: ='2023'!C29 -> 0 | F29: TOTAL PATRIMONIO | G29: =SUM(G18:G28) -> 0 | H29: =SUM(H18:H28) -> 0 | I29: =SUM(I18:I28) -> 0
B30: Activos biologicos | C30: ='2025'!C30 -> 0 | D30: ='2024'!C30 -> 0 | E30: ='2023'!C30 -> 0
B31: Deprec act biologico y amortiz acumulada | C31: ='2025'!C31 -> 0 | D31: ='2024'!C31 -> 0 | E31: ='2023'!C31 -> 0
B32: Desvalorizacióo de activo inmovilizado | C32: ='2025'!C32 -> 0 | D32: ='2024'!C32 -> 0 | E32: ='2023'!C32 -> 0 | F32: TOTAL PASIVO Y PATRIMONIO | G32: =+G29+G15 -> 0 | H32: =+H29+H15 -> 0 | I32: =+I29+I15 -> 0
B33: Activo diferido | C33: ='2025'!C33 -> 0 | D33: ='2024'!C33 -> 0 | E33: ='2023'!C33 -> 0
B34: Otros activos no corrientes | C34: ='2025'!C34 -> 0 | D34: ='2024'!C34 -> 0 | E34: ='2023'!C34 -> 0
B35: TOTAL ACTIVO | C35: =SUM(C4:C34) -> 0 | D35: =SUM(D4:D34) -> 0 | E35: =SUM(E4:E34) -> 0
G37: =+C35-G32 -> 0 | H37: =+D35-H32 -> 0 | I37: =+E35-I32 -> 0
G40: 2025 | H40: 2024 | I40: 2023
B41: ESTADO DE RESULTADO | C41: 2025 | D41: 2024 | E41: 2023 | F41: VENTAS | G41: =+VENTAS_24 -> 0 | H41: =+VENTAS_23 -> 0 | I41: =+VENTAS_22 -> 0
B42: Ventas netas o ing por servicios | C42: ='2025'!C42 -> 0 | D42: ='2024'!C42 -> 0 | E42: ='2023'!C42 -> 0 | F42: UTILIDAD | G42: =+UTI_24 -> 0 | H42: =+UTI_23 -> 0 | I42: =+UTI_22 -> 0
B43: Desc , rebajas y bonif concedidas | C43: =+'2025'!C43 -> 0 | D43: =+'2024'!C43 -> 0 | E43: =+'2023'!C43 -> 0
B44: Ventas netas | C44: =+SUM(C42:C43) -> 0 | D44: =+SUM(D42:D43) -> 0 | E44: =+SUM(E42:E43) -> 0 | F44: Liquidez corriente | G44: =SUM(C4:C23) -> 0 | H44: =SUM(D4:D23) -> 0 | I44: =SUM(E4:E23) -> 0
...

Sheet Comparivo
C2: AÑO | D2: 2025 | E2: 2024 | F2: 2023 | I2: PROYECCIÓN
C3: VENTAS | D3: ='2023-2025'!C42 -> 0 | E3: ='2023-2025'!D42 -> 0 | F3: ='2023-2025'!E42 -> 0
B4: 1 | C4: UTILIDAD NETA | D4: =+'2023-2025'!G42 -> 0 | E4: ='2023-2025'!D71 -> 0 | F4: ='2023-2025'!E71 -> 0 | I4: Ventas
C5: DEPRECIACION ANUAL | D5: =-('2025'!C28-'2024'!C28) -> 0 | E5: =+'2023-2025'!E28-'2023-2025'!D28 -> 0 | I5: Meses
B6: 2 | C6: Monto de depreciación | D6: =IF(D5>=0,D5,0) -> 0 | E6: =IF(E5>=0,E5,0) -> 0 | I6: Anual
B7: 1+2 | C7: CAJA ANUAL | D7: =+D4+D6 -> 0 | E7: =+E4+E6 -> 0 | I7: Utilidad
C8: Pago deuda 12 meses | D8: =(+PASIV_24-'2023-2025'!G9)*0.33 -> 0
C9: Capacidad de pago anual | D9: =D7-D8 -> 0
C10: USS | D10: =+D9/SCORING_FINAL!E6 -> #DIV/0! | E10: =+E4/SCORING_FINAL!E6 -> #DIV/0! | F10: =+F4/SCORING_FINAL!E6 -> #DIV/0!
C11: MODELO A ADQUIRIR | D11: =SCORING_FINAL!K14 -> 0
C12: INGRESO MENSUAL NUEVO PRODUCTO | D12: =SCORING_FINAL!K15 -> 0
C13: MENSUAL | D13: =IFERROR(D10/12,0)+D12 -> 0 | E13: =+E10/12 -> #DIV/0! | F13: =+F10/12 -> #DIV/0!

Sheet SCORING_FINAL
A1: CALIFICACIÓN CREDITICIA | J1: Cuota incial Banco
A2: Cliente | J2: Capacidad pago mensual | K2: =Comparivo!D13 -> 0
A3: RUC | D3: Año base | J3: Cuota mensual estimada (PEN) | K3: =IFERROR($B$7/$K$6,0) -> 0
A4: Fecha inicio actividad | D4: Score Infocorp | J4: Cuota mensual estimada (USD) | K4: =IFERROR($B$6/$K$6,0) -> 0
A5: Historial de pago | D5: % cuota financiada | E5: =+B6/K13 -> #DIV/0! | J5: % Uso de capacidad | K5: =IFERROR(K2/K4,0) -> 0
A6: Monto a financiar (USD) | B6: 0 | D6: Tipo de cambio del día | G6: Tipo de producto | H6: Trucks | J6: Cantidad de letras
A7: Monto a financiar (PEN) | B7: =+E6*B6 -> 0 | D7: Tipo de financiamiento | E7: Financiamiento con leasing | J7: Para leasing: el % financiado no puede superar el 50% de la cuota inicial del banco. | K7: Use desplegables en Año base, Tipo de producto, Tipo de financiamiento e Historial de pago.
A8: Variable | B8: Valor | C8: Puntaje | D8: Peso | E8: Puntaje ponderado | F8: Referencia | H8: Resultado | I8: Valor
A9: Liquidez corriente | B9: =IFERROR(INDEX('2023-2025'!$G$55:$I$55,1,MATCH($E$3,'2023-2025'!$G$54:$I$54,0)),0) -> 0 | C9: =IF(B9>1.5,5,IF(B9>1,4,IF(B9>0.8,3,IF(B9>0.5,2,1)))) -> 1 | D9: 20 | E9: =C9*D9/100 -> 0.2 | F9: Plantilla ratios | H9: Score final (0-5) | I9: =IFERROR(SUM(E9:E15)/(SUM(D9:D15)/100),0) -> 0 | J9: MONTO TOTAL DE LA OP
A10: Historial de pago | B10: =B5 -> 0 | C10: =IF(B10="Excelente",5,IF(B10="Bueno",4,IF(B10="Regular",3,IF(B10="Malo",1,IF(B10="Sin score",3,0))))) -> 0 | D10: 20 | E10: =C10*D10/100 -> 0 | F10: Dato manual | H10: Calificación | I10: =IF(I9>=4.5,"A",IF(I9>=3.5,"B",IF(I9>=3,"C",IF(I9>=2,"D","E")))) -> E | J10: CAMION
A11: Endeudamiento | B11: =IFERROR(INDEX('2023-2025'!$G$59:$I$59,1,MATCH($E$3,'2023-2025'!$G$54:$I$54,0)),0) -> 0 | C11: =IF(B11<=1,5,IF(B11<=2,4,IF(B11<=2.5,3,IF(B11<=4,2,1)))) -> 5 | D11: 20 | E11: =C11*D11/100 -> 1 | F11: Plantilla ratios | H11: Observación | I11: =IF(OR($H$6="",$E$7=""),"Seleccione tipo de producto/financiamiento",IF($E$5>$I$15,"Excede política: requiere aprobación CFO",IF(I10="A","Riesgo muy bajo",IF(I10="B","Riesgo bajo",IF(I10="C","Riesgo medio",IF(I10="D","Riesgo alto","Riesgo muy alto")))))) -> #DIV/0! | J11: NCR | K11: 0
A12: Score Infocorp | B12: =$E$4 -> 0 | C12: =IF(B12>=750,5,IF(B12>=650,4,IF(B12>=550,3,IF(B12>=450,2,1)))) -> 1 | D12: 15 | E12: =C12*D12/100 -> 0.15 | F12: Dato manual | H12: Semáforo | I12: =IF(OR($H$6="",$E$7=""),"Seleccione tipo de producto/financiamiento",IF(OR(I10="D",I10="E"),"🔴 NO APROBADO",IF(I14="Excede política","🟡 REVISAR CFO",IF(I10="C","🟡 REVISAR CFO","🟢 APROBADO")))) -> 🔴 NO APROBADO | J12: CANTIDAD
A13: Rentabilidad | B13: =IFERROR(INDEX('2023-2025'!$G$61:$I$61,1,MATCH($E$3,'2023-2025'!$G$54:$I$54,0)),0) -> 0 | C13: =IF(B13>=0.1,5,IF(B13>=0.08,4,IF(B13>=0.05,3,IF(B13>=0.03,2,1)))) -> 1 | D13: 10 | E13: =C13*D13/100 -> 0.1 | F13: Plantilla ratios | H13: Instrucción | I13: Complete solo celdas amarillas | J13: MONTO TOTAL DE LA OP | K13: =+(K10-K11)*K12 -> 0
A14: Prueba ácida | B14: =IFERROR(INDEX('2023-2025'!$G$57:$I$57,1,MATCH($E$3,'2023-2025'!$G$54:$I$54,0)),0) -> 0 | C14: =IF(B14>1.2,5,IF(B14>1,4,IF(B14>0.8,3,IF(B14>0.6,2,1)))) -> 1 | D14: 5 | E14: =C14*D14/100 -> 0.05 | F14: Plantilla ratios | H14: Validación política | I14: =IF(OR($H$6="",$E$7=""),"Seleccione tipo de producto/financiamiento",IF($E$5>$I$15,"Excede política","Dentro de política")) -> #DIV/0! | J14: MODELO A ADQUIRIR
A15: Uso de capacidad de pago | B15: =K2/K4 -> #DIV/0! | C15: =IF(B15>=1,5,IF(B15>=0.8,4,IF(B15>=0.6,3,IF(B15>=0.4,2,1)))) -> #DIV/0! | D15: 10 | E15: =C15*D15/100 -> #DIV/0! | F15: Dato manual | H15: Límite permitido (%) | I15: =IF($E$7="Financiamiento con leasing",$K$1*0.5,IF($H$6="Buses",0.2,IF($H$6="VCE",0.5,IF($H$6="Trucks",0.3,"")))) -> 0 | J15: INGRESO MENSUAL NUEVO PRODUCTO | K15: =IFERROR(VLOOKUP(K14,LISTAS!G:H,2,FALSE),0)*K12 -> 0
D16: =SUM(D9:D15) -> 100 | H16: Exceso (%) | I16: =IF(OR($H$6="",$E$7="",$I$15=""),"",MAX($E$5-$I$15,0)) -> #DIV/0!
A19: Año | B19: Venta | C19: Rentabilidad | H19: 2026
A20: 2023 | B20: =+'2023-2025'!I41 -> 0 | C20: =+'2023-2025'!I61 -> 0 | H20: # meses
A21: 2024 | B21: =+'2023-2025'!H41 -> 0 | C21: =+'2023-2025'!H61 -> 0
A22: 2025 | B22: =+'2023-2025'!G41 -> 0 | C22: =+'2023-2025'!G61 -> 0
A23: 2026 (Proy) | B23: =+(I19/I20)*12 -> #DIV/0!

Sheet LISTAS
A1: HistorialPago | B1: AnoBase | C1: Semaforo | D1: Notas | E1: TipoFinanciamiento | F1: TipoProducto | G1: ModeloCamion | H1: IngresoMensualUSD
A2: Excelente | B2: 2023 | C2: A | D2: Complete las celdas amarillas | E2: Financiamiento puro | F2: Trucks | G2: FMX 8x4 R | H2: 8500
A3: Bueno | B3: 2024 | C3: B | D3: La calificación toma ratios y montos de forma dinámica | E3: Financiamiento con leasing | F3: VCE | G3: FMX 6x4 R | H3: 7000
A4: Regular | B4: 2025 | C4: C | D4: Use TC del día para convertir USD a PEN | F4: Buses | G4: Tracto | H4: 6000
A5: Malo | G5: VM | H5: 5000
A6: Sin score | G6: Buses | H6: 12000
